# Unit test

## Unit test on Exceptions

```py
import unittest

class MyException(Exception):
    pass

def some_problematic_function():
    raise MyException('[ERR] Shit happens.')

class TestMe(unittest.TestCase):
    def test_something(self):
        self.assertIsNone(None, None)
        with self.assertRaises(MyException) as cm:
            some_problematic_function()
        print(str(cm.exception))


if __name__ == '__main__':
    unittest.main()
```